<!DOCTYPE html>
<html lang="en">

<head>
    <meta charset="UTF-8">
    <meta name="viewport" content="width=device-width, initial-scale=1.0">
    <meta http-equiv="X-UA-Compatible" content="ie=edge">
    <title>Document</title>
</head>

<body>
<script>
    /**
     * 可以理解为一个容器，里面保存着某个未来才会结束的事件（通常是一个异步操作）的结果
     */
    // promise == 构造函数  (英文承诺)
    // 三种状态:pending fulfilled reject
    // promise只要建立 就不可以撤销。

    //基本用法

    // 图片加载

    /*   function loadImg(url) {
           return new Promise((resolve, reject) => {
               let img = new Image()
               img.onload = function () {
                   resolve('done')
                   // 不能直接写 onload = resolve()
               }
               img.onerror = function () {
                   reject('error')
               }
               img.src = url
           })
       }
       loadImg('../es').then(function (value) {
               console.log(value)
           },
           function (data) {
               console.log(data)
           })*/
    //      promise的then方法是添加在promise.prototype上面的
    //      而且then方法返回的是另一个Promise对象。所以可以链式调用。

    // let p = new Promise(function (resolve, reject) {
    //     resolve('resolve中的参数');
    //     reject('123');
    //     console.log('在完成之后的输出');
    // });
    // p.then(function (res) {
    //     console.log(res);
    // }, function (res) {
    //     console.log(res);
    // });
    /**
     * 在promise 构造函数中的函数语句会全部执行。
     * 但是一般来说在resolve函数和reject 函数后面 promise的任务就完成了
     * 所以下面是一种好的写法
     */
    // new Promise((resolve, reject) => {
    //     return resolve(1);
    //     // 后面的语句不会执行
    //     console.log(2);
    // })


    // const p1 = new Promise(function (resolve, reject) {
    //     // ...
    // });
    //
    // const p2 = new Promise(function (resolve, reject) {
    //     // ...
    //     resolve(p1);
    // })
    /**
     * 上面代码中，p1和p2都是 Promise 的实例，但是p2的resolve方法将p1作为参数，
     * 即一个异步操作的结果是返回另一个异步操作。
     * 注意，这时p1的状态就会传递给p2，也就是说，p1的状态决定了p2的状态。
     * 如果p1的状态是pending，那么p2的回调函数就会等待p1的状态改变；
     * 如果p1的状态已经是resolved或者rejected，那么p2的回调函数将会立刻执行
     *
     */

    // 一个栗子
    // const p1 = new Promise(function (resolve, reject) {
    //     setTimeout(() => reject(new Error('fail')), 3000)
    // });
    //
    // const p2 = new Promise(function (resolve, reject) {
    //     setTimeout(() => resolve(p1), 1000)
    // });
    //
    //  p2.then(result => console.log(result))
    //     .catch(error => console.log(error))

    // let p = new Promise(function (resolve, reject) {
    //     setTimeout(function () {
    //         resolve('resolve函数执行完毕');
    //     });
    //     console.lot("123");
    //     });
    // p.then(function (res) {
    //     console.log(res);
    // }, function (res) {
    //     console.log(res);
    // });
    //
    // console.log(12345);
    /**
     * reject 函数的一个作用等同于捕获promise 构造函数执行过程中出现的错误
     * 但是如果构造函数内部直接执行resolve函数 就不会捕获resolve 后面的错误。
     */

     // .finally 方法无论前面的promise最好状态如果 都会执行的函数。







    // let func = new Promise(function (resolve, reject) {
    //     console.log('123')
    //     // 这里就不会触发resolve 函数，因为没写
    //     // 但是如果这里面发生错误就会触发reject 函数 有捕捉错误的能力。
    // })
    // func.then(() => {
    //     console.log('第二次success')
    // }, () => {
    //     console.log('第二次fail')
    // })
    // // 可见 rejuct 是用来捕捉错误的。
    //
    // // 这样无论怎样 第二个then方法返回的都是 resolve  这种写法没有什么意义。
    // // 只有上面的函数发生错误才会调用失败状态。
    //
    // // catch方法返回的还是一个Promise 对象 所以后面还可以接着用then方法。
    //
    // // Promies.all()
    // // 方法传入一个数组promise 对象。
    // // 只有所有的数组promise都变为resolve .all 方法才会返回 resolve 组成的数据。
    // // 只要有一个 promise 返回 reject .all 方法 就返回 那个reject
    //
    // // catch 的用法。
    //
    // let prom = new Promise(function (resolve, reject) {
    //     throw new Error('failed')
    // })
    // prom.catch((err) => {
    //     console.log(err)
    // })
    // // 用来捕捉错误。
    // // 等价写法
    // let pr = new Promise(function (resolve, reject) {
    //     try {
    //         throw new Error('失败')
    //     } catch (e) {
    //         reject(e)
    //     }
    // })
    // pr.catch(function (data) {
    //     console.log(data)
    // })
    //
    // // 第三种写法。
    // let ps = new Promise(function (resolve, reject) {
    //     reject(new Error('第三种失败'))
    // })
    // ps.catch(function (data) {
    //     console.log(data)
    // })
    // // 都是相同的写法。
    //
    // // 但是在reject() 函数执行之后再抛出错误就没有用了。
    //
    //
    // // 需要注意到是promise 中的错误不会被跑到外边
    //
    // let Sa = function () {
    //     return new Promise(function (resolve, reject) {
    //         throw new Error('失败')
    //     })
    // }
    // Sa().then(function () {
    //     console.log('everything is great ')
    // })
    // //虽然浏览器会把错误显示再控制台，但是不会终止下面程序的执行。
    // console.log('12')
    //
    // Promise.resolve().catch(function () {
    //     console.log('failed')
    // }).then(function () {
    //     console.log('success')
    // })
    //
    // // 如果catch前面的函数没有报错。就会忽略catch 方法。而将promise 向下传递。
    //
    //
    //
    // //  还可以用后面的catch 来捕获前面一个catch 里面的错误。

    // let p = new Promise(function (resolve, reject) {
    //     resolve('结果')
    //     })
    // setTimeout(function () {
    //     p.then(function (res) {
    //         console.log(res);
    //     })
    // }, 2000)

    function F() {
        console.log(this)
        function f1() {
            console.log(this)
        }
        f1();
    }

    let f = new F();
    F
</script>
</body>

</html>